Workbook

Sheet Cover & Checks
A1: CMG — FY25 Plan vs Actual and FY26–27 Forecast
A2: Built from public filings. FY25 plan is my own (not company budget). $000.
A4: Blue = typed from filings, black = formula
A10: Sources
A11: FY24 8-K (Feb 4, 2025): https://ir.chipotle.com/2025-02-04-CHIPOTLE-ANNOUNCES-FOURTH-QUARTER-AND-FULL-YEAR-2024-RESULTS
A12: FY25 8-K (Feb 3, 2026): https://ir.chipotle.com/2026-02-03-CHIPOTLE-ANNOUNCES-FOURTH-QUARTER-AND-FULL-YEAR-2025-RESULTS
A13: FY23–24 tied to 10-Ks. FY25 from 8-K, 10-K tie-out pending.
A15: Model check | B15: FY2023 | C15: FY2024 | D15: FY2025 | E15: Status
A16: Balance sheet balances (assets − liabilities − equity) | B16: =Historicals!B39-Historicals!B57 -> 0 | C16: =Historicals!C39-Historicals!C57 -> 0 | D16: =Historicals!D39-Historicals!D57 -> 0 | E16: =IF(AND(ABS(B16)<0.5,ABS(C16)<0.5,ABS(D16)<0.5),"OK","CHECK") -> OK
A17: BS cash + restricted cash − CF ending cash | B17: =Historicals!B26+Historicals!B35-Historicals!B92 -> 0 | C17: =Historicals!C26+Historicals!C35-Historicals!C92 -> 0 | D17: =Historicals!D26+Historicals!D35-Historicals!D92 -> 0 | E17: =IF(AND(ABS(B17)<0.5,ABS(C17)<0.5,ABS(D17)<0.5),"OK","CHECK") -> OK
A18: Revenue ties to filing (model − reported) | B18: =Historicals!B9-9871649 -> 0 | C18: =Historicals!C9-11313853 -> 0 | D18: =Historicals!D9-11925601 -> 0 | E18: =IF(AND(ABS(B18)<0.5,ABS(C18)<0.5,ABS(D18)<0.5),"OK","CHECK") -> OK
A19: Operating income ties to filing | B19: =Historicals!B19-1557813 -> 0 | C19: =Historicals!C19-1916333 -> 0 | D19: =Historicals!D19-1935798 -> 0 | E19: =IF(AND(ABS(B19)<0.5,ABS(C19)<0.5,ABS(D19)<0.5),"OK","CHECK") -> OK
A20: Net income ties to filing | B20: =Historicals!B23-1228737 -> 0 | C20: =Historicals!C23-1534110 -> 0 | D20: =Historicals!D23-1535761 -> 0 | E20: =IF(AND(ABS(B20)<0.5,ABS(C20)<0.5,ABS(D20)<0.5),"OK","CHECK") -> OK
A21: Total assets tie to filing | B21: =Historicals!B39-8044362 -> 0 | C21: =Historicals!C39-9204374 -> 0 | D21: =Historicals!D39-8994531 -> 0 | E21: =IF(AND(ABS(B21)<0.5,ABS(C21)<0.5,ABS(D21)<0.5),"OK","CHECK") -> OK
A22: Total equity ties to filing | B22: =Historicals!B56-3062207 -> 0 | C22: =Historicals!C56-3655546 -> 0 | D22: =Historicals!D56-2830607 -> 0 | E22: =IF(AND(ABS(B22)<0.5,ABS(C22)<0.5,ABS(D22)<0.5),"OK","CHECK") -> OK
A23: Cash from operations ties to filing | B23: =Historicals!B79-1783477 -> 0 | C23: =Historicals!C79-2105076 -> 0 | D23: =Historicals!D79-2113926 -> 0 | E23: =IF(AND(ABS(B23)<0.5,ABS(C23)<0.5,ABS(D23)<0.5),"OK","CHECK") -> OK
A24: Cash from investing ties to filing | B24: =Historicals!B84--946009 -> 0 | C24: =Historicals!C84--837526 -> 0 | D24: =Historicals!D84--35082 -> 0 | E24: =IF(AND(ABS(B24)<0.5,ABS(C24)<0.5,ABS(D24)<0.5),"OK","CHECK") -> OK
A25: Cash from financing ties to filing | B25: =Historicals!B88--660652 -> 0 | C25: =Historicals!C88--1073699 -> 0 | D25: =Historicals!D88--2470898 -> 0 | E25: =IF(AND(ABS(B25)<0.5,ABS(C25)<0.5,ABS(D25)<0.5),"OK","CHECK") -> OK
A26: Restaurant roll-forward (start + open + close + reloc − end) | B26: =Historicals!B95+Historicals!B96+Historicals!B97+Historicals!B98-Historicals!B99 -> 0 | C26: =Historicals!C95+Historicals!C96+Historicals!C97+Historicals!C98-Historicals!C99 -> 0 | D26: =Historicals!D95+Historicals!D96+Historicals!D97+Historicals!D98-Historicals!D99 -> 0 | E26: =IF(AND(ABS(B26)<0.5,ABS(C26)<0.5,ABS(D26)<0.5),"OK","CHECK") -> OK
A27: Comps = transactions + average check (percentage points × 100) | B27: =(Historicals!B103+Historicals!B104-Historicals!B102)*100 -> 0 | C27: =(Historicals!C103+Historicals!C104-Historicals!C102)*100 -> 0 | D27: =(Historicals!D103+Historicals!D104-Historicals!D102)*100 -> 0 | E27: =IF(AND(ABS(B27)<0.05,ABS(C27)<0.05,ABS(D27)<0.05),"OK","CHECK") -> OK
A28: Forecast balance sheet balances (C = FY26E, D = FY27E) | B28: =0 -> 0 | C28: ='BS Forecast'!C35 -> 0 | D28: ='BS Forecast'!D35 -> 0 | E28: =IF(AND(ABS(B28)<0.5,ABS(C28)<0.5,ABS(D28)<0.5),"OK","CHECK") -> OK
A29: FY25 cost variance: volume + rate = total (FY2025 column) | B29: =0 -> 0 | C29: =0 -> 0 | D29: ='FY25 Plan vs Actual'!F19 -> -1.4279067e-10 | E29: =IF(AND(ABS(B29)<0.5,ABS(C29)<0.5,ABS(D29)<0.5),"OK","CHECK") -> OK
A30: FY25 revenue bridge ties to actual revenue (FY2025 column) | B30: =0 -> 0 | C30: =0 -> 0 | D30: ='FY25 Plan vs Actual'!B27 -> 0 | E30: =IF(AND(ABS(B30)<0.5,ABS(C30)<0.5,ABS(D30)<0.5),"OK","CHECK") -> OK
A32: OVERALL MODEL STATUS | E32: =IF(COUNTIF(E16:E30,"CHECK")=0,"ALL OK","FIX") -> ALL OK

Sheet Historicals
A1: CMG Historicals
A2: $000 as filed
A4: Line item | B4: FY2023 | C4: FY2024 | D4: FY2025 | E4: Type | F4: Source
A6: INCOME STATEMENT
A7: Food and beverage revenue | B7: 9804124 | C7: 11247384 | D7: 11866051 | E7: Reported | F7: 10-K / FY25 8-K
A8: Delivery service revenue | B8: 67525 | C8: 66469 | D8: 59550 | E8: Reported | F8: 10-K / FY25 8-K
A9: Total revenue | B9: =SUM(B7:B8) -> 9871649 | C9: =SUM(C7:C8) -> 11313853 | D9: =SUM(D7:D8) -> 11925601 | E9: Derived
A10: Food, beverage and packaging | B10: 2912564 | C10: 3374516 | D10: 3526992 | E10: Reported | F10: 10-K / FY25 8-K
A11: Labor | B11: 2440982 | C11: 2789789 | D11: 2991680 | E11: Reported | F11: 10-K / FY25 8-K
A12: Occupancy | B12: 503264 | C12: 563374 | D12: 624898 | E12: Reported | F12: 10-K / FY25 8-K
A13: Other operating costs | B13: 1428747 | C13: 1568482 | D13: 1755824 | E13: Reported | F13: 10-K / FY25 8-K
A14: General and administrative | B14: 633584 | C14: 697483 | D14: 652017 | E14: Reported | F14: 10-K / FY25 8-K
A15: Depreciation and amortization | B15: 319394 | C15: 335030 | D15: 361382 | E15: Reported | F15: 10-K / FY25 8-K
A16: Pre-opening costs | B16: 36931 | C16: 41897 | D16: 49507 | E16: Reported | F16: 10-K / FY25 8-K
A17: Impairment, closure costs, and asset disposals | B17: 38370 | C17: 26949 | D17: 27503 | E17: Reported | F17: 10-K / FY25 8-K
A18: Total operating expenses | B18: =SUM(B10:B17) -> 8313836 | C18: =SUM(C10:C17) -> 9397520 | D18: =SUM(D10:D17) -> 9989803 | E18: Derived
A19: Income from operations | B19: =B9-B18 -> 1557813 | C19: =C9-C18 -> 1916333 | D19: =D9-D18 -> 1935798 | E19: Derived
A20: Interest and other income, net | B20: 62693 | C20: 93897 | D20: 73721 | E20: Reported | F20: 10-K / FY25 8-K
A21: Income before income taxes | B21: =B19+B20 -> 1620506 | C21: =C19+C20 -> 2010230 | D21: =D19+D20 -> 2009519 | E21: Derived
A22: Provision for income taxes | B22: 391769 | C22: 476120 | D22: 473758 | E22: Reported | F22: 10-K / FY25 8-K
A23: Net income | B23: =B21-B22 -> 1228737 | C23: =C21-C22 -> 1534110 | D23: =D21-D22 -> 1535761 | E23: Derived
A25: BALANCE SHEET (December 31)
A26: Cash and cash equivalents | B26: 560609 | C26: 748537 | D26: 350545 | E26: Reported | F26: 10-K / FY25 8-K
A27: Accounts receivable, net | B27: 115535 | C27: 143963 | D27: 156466 | E27: Reported | F27: 10-K / FY25 8-K
A28: Inventory | B28: 39309 | C28: 48942 | D28: 49508 | E28: Reported | F28: 10-K / FY25 8-K
A29: Prepaid expenses and other current assets | B29: 117462 | C29: 97538 | D29: 120450 | E29: Reported | F29: 10-K / FY25 8-K
A30: Income tax receivable | B30: 52960 | C30: 67229 | D30: 91393 | E30: Reported | F30: 10-K / FY25 8-K
A31: Investments (short-term) | B31: 734838 | C31: 674378 | D31: 698591 | E31: Reported | F31: 10-K / FY25 8-K
A32: Total current assets | B32: =SUM(B26:B31) -> 1620713 | C32: =SUM(C26:C31) -> 1780587 | D32: =SUM(D26:D31) -> 1466953 | E32: Derived
A33: Leasehold improvements, property and equipment, net | B33: 2170038 | C33: 2390126 | D33: 2679361 | E33: Reported | F33: 10-K / FY25 8-K
A34: Long-term investments | B34: 564488 | C34: 868025 | D34: 197123 | E34: Reported | F34: 10-K / FY25 8-K
A35: Restricted cash | B35: 25554 | C35: 29842 | D35: 35364 | E35: Reported | F35: 10-K / FY25 8-K
A36: Operating lease assets | B36: 3578548 | C36: 4000127 | D36: 4463010 | E36: Reported | F36: 10-K / FY25 8-K
A37: Other assets | B37: 63082 | C37: 113728 | D37: 130781 | E37: Reported | F37: 10-K / FY25 8-K
A38: Goodwill | B38: 21939 | C38: 21939 | D38: 21939 | E38: Reported | F38: 10-K / FY25 8-K
A39: Total assets | B39: =B32+SUM(B33:B38) -> 8044362 | C39: =C32+SUM(C33:C38) -> 9204374 | D39: =D32+SUM(D33:D38) -> 8994531 | E39: Derived
A41: Accounts payable | B41: 197646 | C41: 210695 | D41: 212813 | E41: Reported | F41: 10-K / FY25 8-K
A42: Accrued payroll and benefits | B42: 227537 | C42: 261913 | D42: 250126 | E42: Reported | F42: 10-K / FY25 8-K
A43: Accrued liabilities | B43: 147688 | C43: 179747 | D43: 182448 | E43: Reported | F43: 10-K / FY25 8-K
A44: Unearned revenue (mostly gift cards) | B44: 209680 | C44: 238577 | D44: 240375 | E44: Reported | F44: 10-K / FY25 8-K
...

Sheet Analysis
A1: Historical Analysis
A2: $000 unless noted
A4: Metric | B4: FY2023 | C4: FY2024 | D4: FY2025 | E4: Notes
A6: GROWTH & MARGINS
A7: Revenue growth | B7: ="" | C7: =Historicals!C9/Historicals!B9-1 -> 0.14609555 | D7: =Historicals!D9/Historicals!C9-1 -> 0.054070704
A8: Food, beverage & packaging % of revenue | B8: =Historicals!B10/Historicals!B9 -> 0.29504331 | C8: =Historicals!C10/Historicals!C9 -> 0.29826408 | D8: =Historicals!D10/Historicals!D9 -> 0.29574962
A9: Labor % of revenue | B9: =Historicals!B11/Historicals!B9 -> 0.24727196 | C9: =Historicals!C11/Historicals!C9 -> 0.24658169 | D9: =Historicals!D11/Historicals!D9 -> 0.25086199
A10: Occupancy % of revenue | B10: =Historicals!B12/Historicals!B9 -> 0.050980743 | C10: =Historicals!C12/Historicals!C9 -> 0.049795061 | D10: =Historicals!D12/Historicals!D9 -> 0.052399707
A11: Other operating costs % of revenue | B11: =Historicals!B13/Historicals!B9 -> 0.14473235 | C11: =Historicals!C13/Historicals!C9 -> 0.13863376 | D11: =Historicals!D13/Historicals!D9 -> 0.14723149
A12: Restaurant-level margin (non-GAAP) | B12: =(Historicals!B9-Historicals!B10-Historicals!B11-Historicals!B12-Historicals!B13)/Historicals!B9 -> 0.26197163 | C12: =(Historicals!C9-Historicals!C10-Historicals!C11-Historicals!C12-Historicals!C13)/Historicals!C9 -> 0.2667254 | D12: =(Historicals!D9-Historicals!D10-Historicals!D11-Historicals!D12-Historicals!D13)/Historicals!D9 -> 0.25375719
A13: G&A % of revenue | B13: =Historicals!B14/Historicals!B9 -> 0.064182185 | C13: =Historicals!C14/Historicals!C9 -> 0.061648582 | D13: =Historicals!D14/Historicals!D9 -> 0.054673723
A14: Operating margin | B14: =Historicals!B19/Historicals!B9 -> 0.15780677 | C14: =Historicals!C19/Historicals!C9 -> 0.16937934 | D14: =Historicals!D19/Historicals!D9 -> 0.16232289
A15: Effective tax rate | B15: =Historicals!B22/Historicals!B21 -> 0.2417572 | C15: =Historicals!C22/Historicals!C21 -> 0.23684852 | D15: =Historicals!D22/Historicals!D21 -> 0.23575691
A16: Net margin | B16: =Historicals!B23/Historicals!B9 -> 0.1244713 | C16: =Historicals!C23/Historicals!C9 -> 0.13559572 | D16: =Historicals!D23/Historicals!D9 -> 0.1287785
A18: UNIT ECONOMICS
A19: Revenue per average restaurant ($000) | B19: =IF(Historicals!B100="","",Historicals!B9/Historicals!B100) -> 2980.5704 | C19: =IF(Historicals!C100="","",Historicals!C9/Historicals!C100) -> 3158.9705 | D19: =IF(Historicals!D100="","",Historicals!D9/Historicals!D100) -> 3070.4431
A20: Occupancy per average restaurant ($000) | B20: =IF(Historicals!B100="","",Historicals!B12/Historicals!B100) -> 151.95169 | C20: =IF(Historicals!C100="","",Historicals!C12/Historicals!C100) -> 157.30113 | D20: =IF(Historicals!D100="","",Historicals!D12/Historicals!D100) -> 160.89032
A21: Pre-opening cost per opening ($000) | B21: =IF(Historicals!B96="","",Historicals!B16/Historicals!B96) -> 136.27675 | C21: =IF(Historicals!C96="","",Historicals!C16/Historicals!C96) -> 137.81908 | D21: =IF(Historicals!D96="","",Historicals!D16/Historicals!D96) -> 148.22455
A22: Capex per opening ($000, all-in incl. maintenance) | B22: =IF(Historicals!B96="","",-Historicals!B80/Historicals!B96) -> 2069.1181 | C22: =IF(Historicals!C96="","",-Historicals!C80/Historicals!C96) -> 1952.6414 | D22: =IF(Historicals!D96="","",-Historicals!D80/Historicals!D96) -> 1995.018
A23: Comps check: transactions + average check | B23: =IF(Historicals!B103="","",Historicals!B103+Historicals!B104) -> 0.079 | C23: =IF(Historicals!C103="","",Historicals!C103+Historicals!C104) -> 0.074 | D23: =IF(Historicals!D103="","",Historicals!D103+Historicals!D104) -> -0.017
A25: WORKING CAPITAL & CASH
A26: Receivable days (DSO) | B26: =Historicals!B27/Historicals!B9*365 -> 4.2718572 | C26: =Historicals!C27/Historicals!C9*365 -> 4.6444385 | D26: =Historicals!D27/Historicals!D9*365 -> 4.7888647
A27: Inventory days (on food cost) | B27: =Historicals!B28/Historicals!B10*365 -> 4.9261699 | C27: =Historicals!C28/Historicals!C10*365 -> 5.2937458 | D27: =Historicals!D28/Historicals!D10*365 -> 5.123465
A28: Payable days (on food cost) | B28: =Historicals!B41/Historicals!B10*365 -> 24.768826 | C28: =Historicals!C41/Historicals!C10*365 -> 22.789542 | D28: =Historicals!D41/Historicals!D10*365 -> 22.02351
A29: Unearned revenue % of revenue | B29: =Historicals!B44/Historicals!B9 -> 0.021240626 | C29: =Historicals!C44/Historicals!C9 -> 0.021087157 | D29: =Historicals!D44/Historicals!D9 -> 0.020156217
A30: Operating working capital ($000) | B30: =Historicals!B27+Historicals!B28+Historicals!B29-Historicals!B41-Historicals!B42-Historicals!B43-Historicals!B44 -> -510245 | C30: =Historicals!C27+Historicals!C28+Historicals!C29-Historicals!C41-Historicals!C42-Historicals!C43-Historicals!C44 -> -600489 | D30: =Historicals!D27+Historicals!D28+Historicals!D29-Historicals!D41-Historicals!D42-Historicals!D43-Historicals!D44 -> -559338
A31: D&A % of beginning PP&E | B31: ="" | C31: =Historicals!C15/Historicals!B33 -> 0.154389 | D31: =Historicals!D15/Historicals!C33 -> 0.15119789
A32: Cash conversion (CFO / net income) | B32: =Historicals!B79/Historicals!B23 -> 1.4514717 | C32: =Historicals!C79/Historicals!C23 -> 1.3721806 | D32: =Historicals!D79/Historicals!D23 -> 1.3764681
A33: Free cash flow ($000) = CFO + capex | B33: =Historicals!B79+Historicals!B80 -> 1222746 | C33: =Historicals!C79+Historicals!C80 -> 1511473 | D33: =Historicals!D79+Historicals!D80 -> 1447590
A34: Share buybacks as % of free cash flow | B34: =-Historicals!B85/(Historicals!B79+Historicals!B80) -> 0.48444158 | C34: =-Historicals!C85/(Historicals!C79+Historicals!C80) -> 0.66263771 | D34: =-Historicals!D85/(Historicals!D79+Historicals!D80) -> 1.6755545

Sheet Assumptions
A1: Assumptions & Management Guidance
A2: Blue = guidance (reported), yellow = assumption
A4: Driver | B4: Low | C4: High | D4: Model value | E4: Type | F4: Source / reasoning
A5: FY25 PLAN (as of Feb 4, 2025)
A6: Comp sales growth (guided low-mid single digits) | D6: =D7+D8 -> 0.035 | E6: Assumed | F6: 3.5% = middle of guidance; growth slowing (FY23 7.9%, FY24 7.4%, Q4'24 5.4%)
A7: Transactions growth | D7: 0.02 | E7: Assumed | F7: Return-to-office mandates (e.g. Amazon, federal govt, Jan 2025) should help lunch traffic; below FY24's 5.3%
A8: Average check growth | D8: 0.015 | E8: Assumed | F8: Price growth slowing: check +2.1% FY24, +1.4% Q4'24
A9: New company-owned restaurant openings | B9: 315 | C9: 345 | D9: =AVERAGE(B9:C9) -> 330 | E9: Reported | F9: Feb 2025 guidance
A10: Underlying effective tax rate | B10: 0.25 | C10: 0.27 | D10: =AVERAGE(B10:C10) -> 0.26 | E10: Reported | F10: Feb 2025 guidance
A11: Food, beverage & packaging % of revenue | D11: 0.303 | E11: Assumed | F11: Q4'24 exit rate (30.4%); food inflation rising into 2025
A12: Labor % of revenue | D12: 0.252 | E12: Assumed | F12: Q4'24 exit rate (25.2%); wage inflation. Cautious - Q4 is a lower-sales quarter
A13: Occupancy per average restaurant ($000) | D13: ='FY25 Plan vs Actual'!$B$44 -> 162.02016 | E13: Assumed | F13: FY24 rent per average restaurant + 3%
A14: Other operating costs % of revenue | D14: =Historicals!C13/Historicals!C9 -> 0.13863376 | E14: Assumed | F14: Same as FY24
A15: G&A ($000) | D15: ='FY25 Plan vs Actual'!B10 -> 732357.15 | E15: Assumed | F15: FY24 + 5%
A17: FY26 GUIDANCE
A18: Comparable sales growth ('about flat') | B18: 0 | C18: 0 | D18: =AVERAGE(B18:C18) -> 0 | E18: Reported | F18: Feb 2026 guidance (raised Jul 2026)
A19: New restaurant openings (incl. 10–15 partner-operated) | B19: 350 | C19: 370 | D19: =AVERAGE(B19:C19) -> 360 | E19: Reported | F19: Feb 2026 guidance
A20: Underlying effective tax rate | B20: 0.24 | C20: 0.26 | D20: =AVERAGE(B20:C20) -> 0.25 | E20: Reported | F20: Feb 2026 guidance

Sheet FY25 Plan vs Actual
A1: FY25 Plan vs Actual
A2: $000. Plan uses info available as of Feb 4, 2025 only. Variance = actual - plan (for costs, positive = spent more than plan).
A4: Line ($000) | B4: Plan | C4: Actual | D4: Variance $ | E4: Variance % | F4: Volume effect | G4: Rate effect | H4: Notes
A5: Total revenue | B5: =$B$40 -> 12498914 | C5: =Historicals!D9 -> 11925601 | D5: =C5-B5 -> -573313.15 | E5: =IF(B5=0,"",D5/B5) -> -0.045869037 | H5: Sales missed by $573M mainly because fewer customers came in ($551M): visits fell 2.9% vs my plan of +2%. Customers were cutting back on eating out due to economic pressure; the decline started in Q1 2025 and lasted all year. Even after the CEO spoke about returning to transaction growth in Q3, visits were still down 3.2% in Q4.
A6: Food, beverage and packaging | B6: =B5*Assumptions!D11 -> 3787171 | C6: =Historicals!D10 -> 3526992 | D6: =C6-B6 -> -260178.99 | E6: =IF(B6=0,"",D6/B6) -> -0.06870009 | F6: =B6/B5*(C5-B5) -> -173713.88 | G6: =(C6/C5-B6/B5)*C5 -> -86465.103 | H6: Food cost was $260M below plan. $174M is just lower sales (fewer burritos, fewer ingredients). The other $86M is real: food ran 29.6% of sales vs my 30.3% plan, because menu price increases and efficiencies more than offset beef and chicken inflation.
A7: Labor | B7: =B5*Assumptions!D12 -> 3149726.4 | C7: =Historicals!D11 -> 2991680 | D7: =C7-B7 -> -158046.37 | E7: =IF(B7=0,"",D7/B7) -> -0.050177808 | F7: =B7/B5*(C5-B5) -> -144474.91 | G7: =(C7/C5-B7/B5)*C5 -> -13571.452
A8: Occupancy | B8: =$B$45*$B$44 -> 630420.46 | C8: =Historicals!D12 -> 624898 | D8: =C8-B8 -> -5522.461 | E8: =IF(B8=0,"",D8/B8) -> -0.0087599647 | F8: =(Historicals!D100-$B$45)*$B$44 -> -1134.1412 | G8: =(C8/Historicals!D100-$B$44)*Historicals!D100 -> -4388.3198
A9: Other operating costs | B9: =B5*Assumptions!D14 -> 1732771.5 | C9: =Historicals!D13 -> 1755824 | D9: =C9-B9 -> 23052.515 | E9: =IF(B9=0,"",D9/B9) -> 0.01330384 | F9: =B9/B5*(C5-B5) -> -79480.559 | G9: =(C9/C5-B9/B5)*C5 -> 102533.07 | H9: Other operating costs look close to plan (+$23M), but per dollar of sales they ran $103M above plan (14.7% vs 13.9%); lower sales hid it. Likely causes: fixed restaurant costs spread over lower sales, and more marketing and promotions to win customers back (to confirm in FY25 10-K).
A10: General and administrative | B10: =Historicals!C14*(1+$B$46) -> 732357.15 | C10: =Historicals!D14 -> 652017 | D10: =C10-B10 -> -80340.15 | E10: =IF(B10=0,"",D10/B10) -> -0.10970078 | F10: 0 | G10: =D10 -> -80340.15
A11: Depreciation and amortization | B11: =Historicals!C33*$B$47 -> 369009.17 | C11: =Historicals!D15 -> 361382 | D11: =C11-B11 -> -7627.1666 | E11: =IF(B11=0,"",D11/B11) -> -0.020669315 | F11: 0 | G11: =D11 -> -7627.1666
A12: Pre-opening costs | B12: =$B$37*$B$48 -> 45480.296 | C12: =Historicals!D16 -> 49507 | D12: =C12-B12 -> 4026.7039 | E12: =IF(B12=0,"",D12/B12) -> 0.088537329 | F12: =(Historicals!D96-$B$37)*$B$48 -> 551.27632 | G12: =(C12/Historicals!D96-$B$48)*Historicals!D96 -> 3475.4276
A13: Impairment, closure costs | B13: =Historicals!C17 -> 26949 | C13: =Historicals!D17 -> 27503 | D13: =C13-B13 -> 554 | E13: =IF(B13=0,"",D13/B13) -> 0.020557349 | F13: 0 | G13: =D13 -> 554
A14: Income from operations | B14: =B5-SUM(B6:B13) -> 2025029.2 | C14: =Historicals!D19 -> 1935798 | D14: =C14-B14 -> -89231.238 | E14: =IF(B14=0,"",D14/B14) -> -0.044064173
A15: Interest and other income | B15: =Historicals!C20 -> 93897 | C15: =Historicals!D20 -> 73721 | D15: =C15-B15 -> -20176 | E15: =IF(B15=0,"",D15/B15) -> -0.21487374
A16: Provision for income taxes | B16: =(B14+B15)*Assumptions!D10 -> 550920.82 | C16: =Historicals!D22 -> 473758 | D16: =C16-B16 -> -77162.822 | E16: =IF(B16=0,"",D16/B16) -> -0.14006155
A17: Net income | B17: =B14+B15-B16 -> 1568005.4 | C17: =Historicals!D23 -> 1535761 | D17: =C17-B17 -> -32244.416 | E17: =IF(B17=0,"",D17/B17) -> -0.02056397
A18: Operating margin | B18: =B14/B5 -> 0.16201641 | C18: =C14/C5 -> 0.16232289 | D18: =C18-B18 -> 0.00030647528
E19: Check: vol + rate - variance | F19: =SUMPRODUCT(F6:F13+G6:G13-D6:D13) -> -1.4279067e-10
A20: REVENUE BRIDGE: Plan -> Actual
A21: Plan revenue | B21: =$B$40 -> 12498914
A22: Traffic effect (transactions vs plan) | B22: =$B$30*(Historicals!D103-Assumptions!D7) -> -551121.82 | H22: FY24 sales x (actual - plan transaction growth)
A23: Average check effect (vs plan) | B23: =$B$30*(Historicals!D104-Assumptions!D8) -> -33742.152 | H23: FY24 sales x (actual - plan check growth)
A24: New restaurants & other (residual) | B24: =(Historicals!D7-$B$30*(1+Historicals!D102))-$B$38 -> 18469.818 | H24: Plug: actual revenue not explained by comps, minus plan new-unit revenue. Includes gift-card breakage, closures, timing
A25: Delivery revenue effect | B25: =Historicals!D8-$B$39 -> -6919
A26: Actual revenue (bridge) | B26: =SUM(B21:B25) -> 11925601
A27: Check: bridge - reported actual | B27: =B26-Historicals!D9 -> 0
A29: PLAN BUILD - revenue
A30: FY24 food & beverage revenue | B30: =Historicals!C7 -> 11247384
A31: Planned comp sales growth | B31: =Assumptions!D6 -> 0.035
A32: Existing-restaurant revenue | B32: =$B$30*(1+$B$31) -> 11641042 | H32: FY24 sales grown at planned comps
A33: FY24 new-restaurant revenue (derived) | B33: =Historicals!C7-Historicals!B7*(1+Historicals!C102) -> 717754.82 | H33: FY24 sales not explained by comps
A34: Half-year factor (openings spread over the year) | B34: 0.5
A35: FY24 new-restaurant years | B35: =(Historicals!B96+Historicals!C96)*$B$34 -> 287.5 | H35: FY23 openings finishing their ramp + FY24 openings half-year
A36: Revenue per new-restaurant year ($000) | B36: =$B$33/$B$35 -> 2496.5385 | H36: Derived from FY24 - new units run below the average restaurant
A37: Planned FY25 openings | B37: =Assumptions!D9 -> 330
A38: New-restaurant revenue | B38: =(Historicals!C96+$B$37)*$B$34*$B$36 -> 791402.71 | H38: FY24 openings annualizing + FY25 openings half-year
A39: Delivery service revenue | B39: =Historicals!C8 -> 66469 | H39: Held flat
A40: Plan total revenue | B40: =$B$32+$B$38+$B$39 -> 12498914
A42: PLAN BUILD - costs
A43: Rent inflation | B43: 0.03
...

Sheet Scenarios
A1: Forecast Drivers & Scenarios
A2: Change B4 to switch case: 1 = Base, 2 = Upside, 3 = Downside. Column E feeds the forecast.
A4: Scenario switch | B4: 1 | C4: =CHOOSE($B$4,"Base","Upside","Downside") -> Base
A6: Driver | B6: Base | C6: Upside | D6: Downside | E6: Active | F6: Why
A7: H2 2026 comp sales growth | B7: 0.015 | C7: 0.03 | D7: 0 | E7: =CHOOSE($B$4,B7,C7,D7) -> 0.015 | F7: H1 +1.4%, Q2 +2.2%; food-safety headwind into H2. Guidance 'low single digit'
A8: FY2027 comp sales growth | B8: 0.025 | C8: 0.04 | D8: 0 | E8: =CHOOSE($B$4,B8,C8,D8) -> 0.025 | F8: Traffic recovering off a weak 2025 base; price ~1-2%
A9: FY2026 company-owned openings | B9: 345 | C9: 352 | D9: 338 | E9: =CHOOSE($B$4,B9,C9,D9) -> 345 | F9: Guidance 350-370 incl. 10-15 partner-operated; 149 opened in H1
A10: FY2027 company-owned openings | B10: 360 | C10: 380 | D10: 330 | E10: =CHOOSE($B$4,B10,C10,D10) -> 360 | F10: Steady pace toward long-term unit target
A11: Food, bev & packaging % of revenue (H2'26, FY27) | B11: 0.305 | C11: 0.3 | D11: 0.31 | E11: =CHOOSE($B$4,B11,C11,D11) -> 0.305 | F11: H2'25 was 30.1%; H1'26 ran +0.6pt y/y on beef and freight
A12: Labor % of revenue (H2'26, FY27) | B12: 0.256 | C12: 0.252 | D12: 0.26 | E12: =CHOOSE($B$4,B12,C12,D12) -> 0.256 | F12: H2'25 was 25.3%; wage inflation, H1'26 +0.7pt y/y
A13: Other operating costs % of revenue (H2'26, FY27) | B13: 0.155 | C13: 0.15 | D13: 0.16 | E13: =CHOOSE($B$4,B13,C13,D13) -> 0.155 | F13: H2'25 was 15.2%; marketing and utilities up ~1pt in H1'26
A14: G&A growth vs prior period | B14: 0.06 | C14: 0.04 | D14: 0.08 | E14: =CHOOSE($B$4,B14,C14,D14) -> 0.06 | F14: H1'26 G&A +14% (legal, bonuses); expect it to slow
A15: Capex per opening, all-in ($000) | B15: 2000 | C15: 1950 | D15: 2100 | E15: =CHOOSE($B$4,B15,C15,D15) -> 2000 | F15: FY25: $666M / 334 openings = ~$2.0M incl. maintenance
A17: OTHER FORECAST INPUTS (same in every case)
A18: H1 2026 comp sales (reported) | E18: 0.014 | F18: Q2 2026 10-Q
A19: Closures + relocations per year | E19: 15 | F19: FY25: 18, H1'26: 5
A20: Rent inflation per restaurant | E20: 0.03
A21: Impairment, H2 2026 ($000) | E21: 15000 | F21: H1'26 was $23.6M, elevated
A22: Impairment, FY2027 ($000) | E22: 30000 | F22: ~3-year average
A23: Yield on cash + investments | E23: 0.03 | F23: FY25: ~3.2%
A24: Effective tax rate | E24: 0.25 | F24: Guidance 24-26%
A25: Investments ST+LT at Jun 30, 2026 (held to YE) | E25: 546737 | F25: Q2 10-Q: 449,658 + 97,079. Sold down in H1 to fund buybacks
A26: Stock comp FY2026 | E26: 110000 | F26: H1'26: $54.5M
A27: Stock comp FY2027 | E27: 120000
A28: Buybacks FY2026 | E28: 1754905 | F28: H1 actual $1,354.9M + ~$400M in H2
A29: Buybacks FY2027 | E29: 1200000 | F29: Roughly free cash flow, keeps cash ~flat
A30: Tax withholding on stock awards, per year | E30: 50000 | F30: FY25: $49.5M
A32: SCENARIO RESULTS (pasted values, re-run by changing B4)
A33: $000 | B33: Base | C33: Upside | D33: Downside
A34: FY2026 revenue | B34: 12931956 | C34: 13021761 | D34: 12842152
A35: FY2026 operating income | B35: 1833101 | C35: 1955609 | D35: 1713108
A36: FY2026 operating margin | B36: 0.1417 | C36: 0.1502 | D36: 0.1334
A37: FY2027 revenue | B37: 14150177 | C37: 14471827 | D37: 13690106
A38: FY2027 operating income | B38: 1946926 | C38: 2256250 | D38: 1608919
A39: FY2027 operating margin | B39: 0.1376 | C39: 0.1559 | D39: 0.1175
A40: FY2027 net income | B40: 1477510 | C40: 1711689 | D40: 1221496
A41: FY2027 ending cash | B41: 390563 | C41: 709314 | D41: 35723

Sheet IS Forecast
A1: Income Statement Forecast
A2: $000. FY26 = H1 actual (Q2 10-Q) + H2 forecast. FY27 full year.
A4: Line ($000) | B4: FY2025A | C4: H1 2026A | D4: H2 2026E | E4: FY2026E | F4: FY2027E | G4: Method
A6: RESTAURANTS
A7: Company-owned restaurants, end of period | B7: =Historicals!D99 -> 4042 | C7: 4186 | D7: =E7 -> 4372 | E7: =B7+Scenarios!$E$9-Scenarios!$E$19 -> 4372 | F7: =E7+Scenarios!$E$10-Scenarios!$E$19 -> 4717 | G7: Prior year end + openings - closures/relocations
A8: Openings | B8: =Historicals!D96 -> 334 | C8: 149 | D8: =E8-C8 -> 196 | E8: =Scenarios!$E$9 -> 345 | F8: =Scenarios!$E$10 -> 360
A9: Average restaurants | B9: =Historicals!D100 -> 3884 | D9: =(C7+D7)/2 -> 4279 | E9: =(B7+E7)/2 -> 4207 | F9: =(E7+F7)/2 -> 4544.5
A11: REVENUE BUILD
A12: H2 2025 revenue (FY25 - H1 25) | D12: =Historicals!D9-'H1 2026 Checkpoint'!B5 -> 5986955 | G12: Base for H2 growth
A13: H1 2026 total revenue growth | C13: ='H1 2026 Checkpoint'!C5/'H1 2026 Checkpoint'!B5-1 -> 0.083884104
A14: of which new restaurants (total - comps) | C14: =C13-Scenarios!$E$18 -> 0.069884104 | D14: =C14 -> 0.069884104 | G14: Assume H2 new-unit contribution = H1
A15: Comp sales growth | B15: =Historicals!D102 -> -0.017 | C15: =Scenarios!$E$18 -> 0.014 | D15: =Scenarios!$E$7 -> 0.015 | F15: =Scenarios!$E$8 -> 0.025
A16: Revenue per new-restaurant year ($000) | B16: =(Historicals!D7-Historicals!C7*(1+Historicals!D102))/((Historicals!C96+Historicals!D96)*0.5) -> 2538.7854 | G16: Derived from FY25: revenue not explained by comps / new-unit years
A18: INCOME STATEMENT
A19: Total revenue | B19: =Historicals!D9 -> 11925601 | C19: ='H1 2026 Checkpoint'!C5 -> 6436804 | D19: =D12*(1+D14+D15) -> 6495152.3 | E19: =C19+D19 -> 12931956 | F19: =E19*(1+F15)+(Scenarios!$E$9+Scenarios!$E$10)*0.5*B16 -> 14150177 | G19: H2: H2'25 x (1 + new-unit + comp). FY27: FY26 x (1 + comp) + new-unit revenue
A20: Food, beverage and packaging | B20: =Historicals!D10 -> 3526992 | C20: ='H1 2026 Checkpoint'!C6 -> 1906919 | D20: =D19*Scenarios!$E$11 -> 1981021.5 | E20: =C20+D20 -> 3887940.5 | F20: =F19*Scenarios!$E$11 -> 4315804 | G20: % of revenue
A21: Labor | B21: =Historicals!D11 -> 2991680 | C21: ='H1 2026 Checkpoint'!C7 -> 1641861 | D21: =D19*Scenarios!$E$12 -> 1662759 | E21: =C21+D21 -> 3304620 | F21: =F19*Scenarios!$E$12 -> 3622445.3 | G21: % of revenue
A22: Occupancy | B22: =Historicals!D12 -> 624898 | C22: ='H1 2026 Checkpoint'!C8 -> 344091 | D22: =D9*Historicals!D12/Historicals!D100*(1+Scenarios!$E$20)/2 -> 354551.58 | E22: =C22+D22 -> 698642.58 | F22: =F9*Historicals!D12/Historicals!D100*(1+Scenarios!$E$20)^2 -> 775694.07 | G22: Avg restaurants x FY25 rent per restaurant, +3%/yr
A23: Other operating costs | B23: =Historicals!D13 -> 1755824 | C23: ='H1 2026 Checkpoint'!C9 -> 980407 | D23: =D19*Scenarios!$E$13 -> 1006748.6 | E23: =C23+D23 -> 1987155.6 | F23: =F19*Scenarios!$E$13 -> 2193277.4 | G23: % of revenue
A24: General and administrative | B24: =Historicals!D14 -> 652017 | C24: ='H1 2026 Checkpoint'!C10 -> 394191 | D24: =(Historicals!D14-'H1 2026 Checkpoint'!B10)*(1+Scenarios!$E$14) -> 325507.98 | E24: =C24+D24 -> 719698.98 | F24: =E24*(1+Scenarios!$E$14) -> 762880.92 | G24: H2'25 / FY26 grown
A25: Depreciation and amortization | B25: =Historicals!D15 -> 361382 | C25: ='H1 2026 Checkpoint'!C11 -> 195045 | D25: =Historicals!D33*Historicals!D15/Historicals!C33-C25 -> 210068.72 | E25: =C25+D25 -> 405113.72 | F25: ='BS Forecast'!C13*Historicals!D15/Historicals!C33 -> 448187.92 | G25: % of beginning PP&E (FY25 rate)
A26: Pre-opening costs | B26: =Historicals!D16 -> 49507 | C26: ='H1 2026 Checkpoint'!C12 -> 28005 | D26: =D8*Historicals!D16/Historicals!D96 -> 29052.012 | E26: =C26+D26 -> 57057.012 | F26: =F8*Historicals!D16/Historicals!D96*1.03 -> 54961.663 | G26: Openings x FY25 cost per opening
A27: Impairment, closure costs, asset disposals | B27: =Historicals!D17 -> 27503 | C27: ='H1 2026 Checkpoint'!C13 -> 23627 | D27: =Scenarios!$E$21 -> 15000 | E27: =C27+D27 -> 38627 | F27: =Scenarios!$E$22 -> 30000 | G27: Input
A28: Income from operations | B28: =Historicals!D19 -> 1935798 | C28: =C19-SUM(C20:C27) -> 922658 | D28: =D19-SUM(D20:D27) -> 910442.96 | E28: =E19-SUM(E20:E27) -> 1833101 | F28: =F19-SUM(F20:F27) -> 1946925.7
A29: Interest and other income | B29: =Historicals!D20 -> 73721 | C29: 16419 | D29: =(228199+Scenarios!$E$25)*Scenarios!$E$23/2 -> 11624.04 | E29: =C29+D29 -> 28043.04 | F29: =('BS Forecast'!C7+'BS Forecast'!C12)*Scenarios!$E$23 -> 23088.27 | G29: Cash + investments x yield (beginning of period)
A30: Income before taxes | B30: =B28+B29 -> 2009519 | C30: =C28+C29 -> 939077 | D30: =D28+D29 -> 922067 | E30: =E28+E29 -> 1861144 | F30: =F28+F29 -> 1970014
A31: Provision for income taxes | B31: =Historicals!D22 -> 473758 | C31: 232706 | D31: =D30*Scenarios!$E$24 -> 230516.75 | E31: =C31+D31 -> 463222.75 | F31: =F30*Scenarios!$E$24 -> 492503.49 | G31: Pre-tax x 25%
A32: Net income | B32: =B30-B31 -> 1535761 | C32: =C30-C31 -> 706371 | D32: =D30-D31 -> 691550.25 | E32: =E30-E31 -> 1397921.3 | F32: =F30-F31 -> 1477510.5
A34: KEY RATIOS
A35: Revenue growth (y/y) | C35: ='H1 2026 Checkpoint'!C5/'H1 2026 Checkpoint'!B5-1 -> 0.083884104 | D35: =D19/D12-1 -> 0.084884104 | E35: =E19/B19-1 -> 0.08438613 | F35: =F19/E19-1 -> 0.094202355
A36: Restaurant-level margin | B36: =1-SUM(B20:B23)/B19 -> 0.25375719 | C36: =1-SUM(C20:C23)/C19 -> 0.24290409 | D36: =1-SUM(D20:D23)/D19 -> 0.22941289 | E36: =1-SUM(E20:E23)/E19 -> 0.23612805 | F36: =1-SUM(F20:F23)/F19 -> 0.22918132
A37: Operating margin | B37: =B28/B19 -> 0.16232289 | C37: =C28/C19 -> 0.14334101 | D37: =D28/D19 -> 0.14017269 | E37: =E28/E19 -> 0.1417497 | F37: =F28/F19 -> 0.1375902

Sheet BS Forecast
A1: Balance Sheet Forecast
A2: $000, December 31. Cash comes from the cash flow statement.
A4: Line ($000) | B4: FY2025A | C4: FY2026E | D4: FY2027E | E4: Method
A6: ASSETS
A7: Cash and cash equivalents | B7: =Historicals!D26 -> 350545 | C7: ='CF Forecast'!C26 -> 222871.99 | D7: ='CF Forecast'!D26 -> 390563.4 | E7: From CF Forecast ending cash
A8: Accounts receivable | B8: =Historicals!D27 -> 156466 | C8: ='IS Forecast'!E19*Historicals!D27/Historicals!D9 -> 169669.56 | D8: ='IS Forecast'!F19*Historicals!D27/Historicals!D9 -> 185652.83 | E8: FY25 days of revenue
A9: Inventory | B9: =Historicals!D28 -> 49508 | C9: ='IS Forecast'!E20*Historicals!D28/Historicals!D10 -> 54574.594 | D9: ='IS Forecast'!F20*Historicals!D28/Historicals!D10 -> 60580.468 | E9: FY25 days of food cost
A10: Prepaid and other current assets | B10: =Historicals!D29 -> 120450 | C10: ='IS Forecast'!E19*Historicals!D29/Historicals!D9 -> 130614.31 | D10: ='IS Forecast'!F19*Historicals!D29/Historicals!D9 -> 142918.48 | E10: FY25 % of revenue
A11: Income tax receivable | B11: =Historicals!D30 -> 91393 | C11: =B11 -> 91393 | D11: =C11 -> 91393 | E11: Held flat
A12: Investments (ST + LT) | B12: =Historicals!D31+Historicals!D34 -> 895714 | C12: =Scenarios!$E$25 -> 546737 | D12: =C12 -> 546737 | E12: Jun 30, 2026 balance, then flat
A13: PP&E, net | B13: =Historicals!D33 -> 2679361 | C13: =B13-'CF Forecast'!C17-'IS Forecast'!E25 -> 2964247.3 | D13: =C13-'CF Forecast'!D17-'IS Forecast'!F25 -> 3257659.4 | E13: Beginning + capex - D&A
A14: Restricted cash | B14: =Historicals!D35 -> 35364 | C14: =B14 -> 35364 | D14: =C14 -> 35364 | E14: Held flat
A15: Operating lease assets | B15: =Historicals!D36 -> 4463010 | C15: =B15*'IS Forecast'!E7/'IS Forecast'!B7 -> 4827382.4 | D15: =C15*'IS Forecast'!F7/'IS Forecast'!E7 -> 5208317.2 | E15: Grows with restaurant count
A16: Other assets + goodwill | B16: =Historicals!D37+Historicals!D38 -> 152720 | C16: =B16 -> 152720 | D16: =C16 -> 152720 | E16: Held flat
A17: Total assets | B17: =SUM(B7:B16) -> 8994531 | C17: =SUM(C7:C16) -> 9195574.2 | D17: =SUM(D7:D16) -> 10071906
A19: LIABILITIES
A20: Accounts payable | B20: =Historicals!D41 -> 212813 | C20: ='IS Forecast'!E20*Historicals!D41/Historicals!D10 -> 234592.05 | D20: ='IS Forecast'!F20*Historicals!D41/Historicals!D10 -> 260408.64 | E20: FY25 days of food cost
A21: Accrued payroll and benefits | B21: =Historicals!D42 -> 250126 | C21: ='IS Forecast'!E21*Historicals!D42/Historicals!D11 -> 276290.04 | D21: ='IS Forecast'!F21*Historicals!D42/Historicals!D11 -> 302862.53 | E21: FY25 % of labor
A22: Accrued liabilities | B22: =Historicals!D43 -> 182448 | C22: ='IS Forecast'!E19*Historicals!D43/Historicals!D9 -> 197844.08 | D22: ='IS Forecast'!F19*Historicals!D43/Historicals!D9 -> 216481.46 | E22: FY25 % of revenue
A23: Unearned revenue | B23: =Historicals!D44 -> 240375 | C23: ='IS Forecast'!E19*Historicals!D44/Historicals!D9 -> 260659.32 | D23: ='IS Forecast'!F19*Historicals!D44/Historicals!D9 -> 285214.04 | E23: FY25 % of revenue
A24: Operating lease liabilities (current + LT) | B24: =Historicals!D45+Historicals!D47 -> 5075814 | C24: =B24*'IS Forecast'!E7/'IS Forecast'!B7 -> 5490217.4 | D24: =C24*'IS Forecast'!F7/'IS Forecast'!E7 -> 5923457.4 | E24: Grows with restaurant count
A25: Deferred tax + other liabilities | B25: =Historicals!D48+Historicals!D49 -> 202348 | C25: =B25 -> 202348 | D25: =C25 -> 202348 | E25: Held flat
A26: Total liabilities | B26: =SUM(B20:B25) -> 6163924 | C26: =SUM(C20:C25) -> 6661950.9 | D26: =SUM(D20:D25) -> 7190772
A28: EQUITY
A29: Common stock + APIC | B29: =Historicals!D51+Historicals!D52 -> 2217988 | C29: =B29+Scenarios!$E$26 -> 2327988 | D29: =C29+Scenarios!$E$27 -> 2447988 | E29: Prior + stock comp
A30: AOCI | B30: =Historicals!D54 -> -7289 | C30: =B30 -> -7289 | D30: =C30 -> -7289 | E30: Held flat
A31: Retained earnings | B31: =Historicals!D55 -> 619908 | C31: =B31+'IS Forecast'!E32-Scenarios!$E$28-Scenarios!$E$30 -> 212924.25 | D31: =C31+'IS Forecast'!F32-Scenarios!$E$29-Scenarios!$E$30 -> 440434.73 | E31: Prior + net income - buybacks - tax withholding
A32: Total equity | B32: =SUM(B29:B31) -> 2830607 | C32: =SUM(C29:C31) -> 2533623.3 | D32: =SUM(D29:D31) -> 2881133.7
A33: Total liabilities and equity | B33: =B26+B32 -> 8994531 | C33: =C26+C32 -> 9195574.2 | D33: =D26+D32 -> 10071906
A35: Check: assets - liabilities - equity | B35: =B17-B33 -> 0 | C35: =C17-C33 -> 0 | D35: =D17-D33 -> 0 | E35: Must be 0

Sheet CF Forecast
A1: Cash Flow Forecast
A2: $000, indirect method. Ending cash feeds the balance sheet.
A4: Line ($000) | B4: FY2025A | C4: FY2026E | D4: FY2027E | E4: Note
A5: Net income | B5: =Historicals!D23 -> 1535761 | C5: ='IS Forecast'!E32 -> 1397921.3 | D5: ='IS Forecast'!F32 -> 1477510.5
A6: Depreciation and amortization | B6: =Historicals!D15 -> 361382 | C6: ='IS Forecast'!E25 -> 405113.72 | D6: ='IS Forecast'!F25 -> 448187.92
A7: Stock-based compensation | B7: =Historicals!D65 -> 119543 | C7: =Scenarios!$E$26 -> 110000 | D7: =Scenarios!$E$27 -> 120000
A8: Change: accounts receivable | C8: =-('BS Forecast'!C8-'BS Forecast'!B8) -> -13203.56 | D8: =-('BS Forecast'!D8-'BS Forecast'!C8) -> -15983.272
A9: Change: inventory | C9: =-('BS Forecast'!C9-'BS Forecast'!B9) -> -5066.5939 | D9: =-('BS Forecast'!D9-'BS Forecast'!C9) -> -6005.8737
A10: Change: prepaid and other | C10: =-('BS Forecast'!C10-'BS Forecast'!B10) -> -10164.309 | D10: =-('BS Forecast'!D10-'BS Forecast'!C10) -> -12304.176
A11: Change: accounts payable | C11: =('BS Forecast'!C20-'BS Forecast'!B20) -> 21779.047 | D11: =('BS Forecast'!D20-'BS Forecast'!C20) -> 25816.595
A12: Change: accrued payroll | C12: =('BS Forecast'!C21-'BS Forecast'!B21) -> 26164.038 | D12: =('BS Forecast'!D21-'BS Forecast'!C21) -> 26572.488
A13: Change: accrued liabilities | C13: =('BS Forecast'!C22-'BS Forecast'!B22) -> 15396.081 | D13: =('BS Forecast'!D22-'BS Forecast'!C22) -> 18637.378
A14: Change: unearned revenue | C14: =('BS Forecast'!C23-'BS Forecast'!B23) -> 20284.316 | D14: =('BS Forecast'!D23-'BS Forecast'!C23) -> 24554.722
A15: Change: lease liabilities net of lease assets | C15: =('BS Forecast'!C24-'BS Forecast'!B24)-('BS Forecast'!C15-'BS Forecast'!B15) -> 50031.004 | D15: =('BS Forecast'!D24-'BS Forecast'!C24)-('BS Forecast'!D15-'BS Forecast'!C15) -> 52305.141
A16: Cash from operations | B16: =Historicals!D79 -> 2113926 | C16: =SUM(C5:C15) -> 2018255 | D16: =SUM(D5:D15) -> 2159291.4 | E16: FY25A is reported total; FY25 detail on Historicals
A17: Capital expenditures | B17: =Historicals!D80 -> -666336 | C17: =-'IS Forecast'!E8*Scenarios!$E$15 -> -690000 | D17: =-'IS Forecast'!F8*Scenarios!$E$15*1.03 -> -741600 | E17: Openings x capex per opening
A18: Net sale/(purchase) of investments | B18: =Historicals!D81+Historicals!D82+Historicals!D83 -> 631254 | C18: ='BS Forecast'!B12-'BS Forecast'!C12 -> 348977 | D18: ='BS Forecast'!C12-'BS Forecast'!D12 -> 0
A19: Cash from investing | B19: =Historicals!D84 -> -35082 | C19: =C17+C18 -> -341023 | D19: =D17+D18 -> -741600
A20: Share repurchases | B20: =Historicals!D85 -> -2425516 | C20: =-Scenarios!$E$28 -> -1754905 | D20: =-Scenarios!$E$29 -> -1200000
A21: Tax withholding + other | B21: =Historicals!D86+Historicals!D87 -> -45382 | C21: =-Scenarios!$E$30 -> -50000 | D21: =-Scenarios!$E$30 -> -50000
A22: Cash from financing | B22: =Historicals!D88 -> -2470898 | C22: =C20+C21 -> -1804905 | D22: =D20+D21 -> -1250000
A24: Net change in cash | C24: =C16+C19+C22 -> -127673.01 | D24: =D16+D19+D22 -> 167691.41
A25: Beginning cash | C25: ='BS Forecast'!B7 -> 350545 | D25: =C26 -> 222871.99
A26: Ending cash | C26: =C25+C24 -> 222871.99 | D26: =D25+D24 -> 390563.4 | E26: -> BS Forecast
A28: Free cash flow (CFO + capex) | B28: =B16+B17 -> 1447590 | C28: =C16+C17 -> 1328255 | D28: =D16+D17 -> 1417691.4

Sheet H1 2026 Checkpoint
A1: H1 2026 vs H1 2025
A2: $000. Source: Q2 2026 10-Q
A4: Line ($000) | B4: H1 2025 | C4: H1 2026 | D4: Change $ | E4: Change % | F4: % of rev H1 2025 | G4: % of rev H1 2026
A5: Total revenue | B5: 5938646 | C5: 6436804 | D5: =C5-B5 -> 498158 | E5: =C5/B5-1 -> 0.083884104 | F5: =B5/B$5 -> 1 | G5: =C5/C$5 -> 1
A6: Food, beverage and packaging | B6: 1724392 | C6: 1906919 | D6: =C6-B6 -> 182527 | E6: =C6/B6-1 -> 0.10585006 | F6: =B6/B$5 -> 0.29036787 | G6: =C6/C$5 -> 0.29625246
A7: Labor | B7: 1474487 | C7: 1641861 | D7: =C7-B7 -> 167374 | E7: =C7/B7-1 -> 0.11351338 | F7: =B7/B$5 -> 0.24828673 | G7: =C7/C$5 -> 0.25507395
A8: Occupancy | B8: 304091 | C8: 344091 | D8: =C8-B8 -> 40000 | E8: =C8/B8-1 -> 0.13153957 | F8: =B8/B$5 -> 0.051205443 | G8: =C8/C$5 -> 0.053456809
A9: Other operating costs | B9: 843824 | C9: 980407 | D9: =C9-B9 -> 136583 | E9: =C9/B9-1 -> 0.16186195 | F9: =B9/B$5 -> 0.1420903 | G9: =C9/C$5 -> 0.1523127
A10: General and administrative | B10: 344934 | C10: 394191 | D10: =C10-B10 -> 49257 | E10: =C10/B10-1 -> 0.14280123 | F10: =B10/B$5 -> 0.058082937 | G10: =C10/C$5 -> 0.061240174
A11: Depreciation and amortization | B11: 178156 | C11: 195045 | D11: =C11-B11 -> 16889 | E11: =C11/B11-1 -> 0.09479894 | F11: =B11/B$5 -> 0.029999431 | G11: =C11/C$5 -> 0.030301529
A12: Pre-opening costs | B12: 18820 | C12: 28005 | D12: =C12-B12 -> 9185 | E12: =C12/B12-1 -> 0.48804463 | F12: =B12/B$5 -> 0.0031690725 | G12: =C12/C$5 -> 0.0043507617
A13: Impairment, closure costs, and asset disposals | B13: 11635 | C13: 23627 | D13: =C13-B13 -> 11992 | E13: =C13/B13-1 -> 1.0306833 | F13: =B13/B$5 -> 0.0019592008 | G13: =C13/C$5 -> 0.0036706104
A14: Income from operations | B14: =B5-SUM(B6:B13) -> 1038307 | C14: =C5-SUM(C6:C13) -> 922658 | D14: =C14-B14 -> -115649 | E14: =C14/B14-1 -> -0.11138228 | F14: =B14/B$5 -> 0.17483901 | G14: =C14/C$5 -> 0.14334101
A15: Check: operating income ties to 10-Q (model − reported) | B15: =B14-1038307 -> 0 | C15: =C14-922658 -> 0
A17: OPERATING KPIs (six months)
A18: Company-owned restaurants at June 30 | B18: 3839 | C18: 4186
A19: Openings (six months) | B19: 118 | C19: 149
A20: Comparable restaurant sales | B20: -0.023 | C20: 0.014
A21: Transactions | B21: -0.037 | C21: 0.008
A22: Average check | B22: 0.014 | C22: 0.006
A23: Menu price increase | B23: 0.024 | C23: 0.013
A24: Q2 alone: comparable sales | B24: -0.04 | C24: 0.022
